<?xml version="1.0"?>
<robot xmlns:xacro="http://www.ros.org/wiki/xacro">

<!--#######################################################################################################################################-->
<!--include the helpers with fixed parameters-->
<!--#######################################################################################################################################-->
  <xacro:include filename="$(find fanuc_m16ib_description)/urdf/materials.urdf.xacro" />


<!--#######################################################################################################################################-->
<!--set some parameters with default values used by the macros (kinematics description, simulation and control)-->
<!--#######################################################################################################################################-->

  <xacro:macro name="fanuc_m16ib" params="
    name
    tf_prefix
    parent
    *origin
    generate_ros2_control_tag
    use_mock_hardware
    initial_positions:=${dict(joint1=0.0,joint2=0.0,joint3=0.0,joint4=0.0,joint5=0.0,joint6=0.0)}"
  >


<!--#######################################################################################################################################-->
<!--include ros2 control and create an instance if param generate_ros2_control_tag == true and pass necessary params-->
<!--#######################################################################################################################################-->

    <xacro:if value="${generate_ros2_control_tag}">
        <!-- ros2 control include -->
        <xacro:include filename="$(find fanuc_m16ib_description)/urdf/fanuc_m16ib_ros2_control.urdf.xacro" />
        <!-- ros2 control instance -->
        <xacro:fanuc_m16ib_ros2_control
          name="${name}"
          use_mock_hardware="${use_mock_hardware}"
          tf_prefix="${tf_prefix}"
          initial_positions="${initial_positions}"
        />
    </xacro:if>


<!--#######################################################################################################################################-->
<!--define the main kinematic chain with links and joints -->
<!--#######################################################################################################################################-->
    <xacro:materials tf_prefix="${tf_prefix}"/>

    <!-- Joint 0 fix Base to parent passed in the main_urdf.xacro-->
    <joint name="${tf_prefix}robotarm_to_parent" type="fixed">
        <parent link="${parent}"/>
        <child link="${tf_prefix}base_link"/>
    </joint>

    <!-- Link0 = Base -->
    <link name="${tf_prefix}base_link">
      <origin xyz="0 0 0"/>
      <visual>
        <geometry>
          <mesh filename="package://fanuc_m16ib_description/meshes/visual/base.stl" scale="0.001 0.001 0.001"/>
        </geometry>
        <material name="${tf_prefix}grey"/>
      </visual>
      <collision>
        <origin xyz="0 0 0"/>
        <geometry>
          <mesh filename="package://fanuc_m16ib_description/meshes/collision/base.stl" scale="0.001 0.001 0.001"/>
        </geometry>
        <material name="${tf_prefix}red"/>
      </collision>
    </link>

    <!-- Joint 1 -->
    <joint name="${tf_prefix}joint1" type="revolute">
        <origin xyz="0 0 0.245" rpy="0 0 0"/> 
        <parent link="${tf_prefix}base_link"/>
        <child link="${tf_prefix}link_1"/>
        <axis xyz="0.0 0.0 1.0"/>
        <limit lower="-2.697" upper="2.697" velocity="2.88" effort="1000"/> 
    </joint>

    <!-- Link1 -->
    <link name="${tf_prefix}link_1">
      <visual>
        <origin xyz="0 0 0" rpy="0 0 0"/>
        <geometry>
          <mesh filename="package://fanuc_m16ib_description/meshes/visual/link1.stl" scale="0.001 0.001 0.001"/>
        </geometry>
        <material name="${tf_prefix}yellow"/>
      </visual>
      <collision>
        <origin xyz="0 0 0" rpy = "0 0 0"/>
        <geometry>
          <mesh filename="package://fanuc_m16ib_description/meshes/collision/link1.stl" scale="0.001 0.001 0.001"/>
        </geometry>
        <material name="${tf_prefix}red"/>
      </collision>
    </link>

    <!-- Joint 2 <limit lower="-1.5707" upper="2.9725" velocity="2.88" effort="1000"/> -->
    <joint name="${tf_prefix}joint2" type="revolute">
        <origin xyz="-0.143 0.15 0.28" rpy="1.5707 0 -1.5707"/> 
        <parent link="${tf_prefix}link_1"/>
        <child link="${tf_prefix}link_2"/>
        <axis xyz="0.0 0.0 1.0"/>
        <limit lower="-1.0" upper="1.0" velocity="2.88" effort="1000"/> 
    </joint>

    <!-- Link2 -->
    <link name="${tf_prefix}link_2">
      <visual>
        <origin xyz="0 0 0" rpy="0 0 0"/>
        <geometry>
          <mesh filename="package://fanuc_m16ib_description/meshes/visual/link2.stl" scale="0.001 0.001 0.001"/>
        </geometry>
        <material name="${tf_prefix}yellow"/>
      </visual>
      <collision>
        <origin xyz="0 0 0" rpy = "0 0 0"/>
        <geometry>
          <mesh filename="package://fanuc_m16ib_description/meshes/collision/link2.stl" scale="0.001 0.001 0.001"/>
        </geometry>
        <material name="${tf_prefix}red"/>
      </collision>
    </link>

    <!-- Joint 2_mimic -->
    <joint name="${tf_prefix}joint2_mimic" type="revolute">
        <mimic joint="${tf_prefix}joint2" multiplier="1" offset="0"/>
        <origin xyz="0 0.770 0.0189" rpy="0 3.1415 0"/> 
        <parent link="${tf_prefix}link_2"/>
        <child link="${tf_prefix}link_2_mimic"/>
        <axis xyz="0.0 0.0 1.0"/>
        <limit lower="-1.5707" upper="2.9725" velocity="2.88" effort="1000"/> 
    </joint>

    <!-- Link2_mimic -->
    <link name="${tf_prefix}link_2_mimic"/>  

    <!-- Joint 3 -->
    <joint name="${tf_prefix}joint3" type="revolute">
        <origin xyz="0 0 0" rpy="0 0 0"/> 
        <parent link="${tf_prefix}link_2_mimic"/>
        <child link="${tf_prefix}link_3"/>
        <axis xyz="0.0 0.0 1.0"/>
        <limit lower="-2.967" upper="5.061" velocity="3.05" effort="1000"/> 
    </joint>

    <!-- Link3 -->
    <link name="${tf_prefix}link_3">
      <visual>
        <origin xyz="0 0 0" rpy="0 0 0"/>
        <geometry>
          <mesh filename="package://fanuc_m16ib_description/meshes/visual/link3.stl" scale="0.001 0.001 0.001"/>
        </geometry>
        <material name="${tf_prefix}yellow"/>
      </visual>
      <collision>
        <origin xyz="0 0 0" rpy = "0 0 0"/>
        <geometry>
          <mesh filename="package://fanuc_m16ib_description/meshes/collision/link3.stl" scale="0.001 0.001 0.001"/>
        </geometry>
        <material name="${tf_prefix}red"/>
      </collision>
    </link>

    <!-- Joint 4 -->
    <joint name="${tf_prefix}joint4" type="revolute">
        <origin xyz="0.184575 0.099755 0.163294" rpy="0 -1.5707 0"/> 
        <parent link="${tf_prefix}link_3"/>
        <child link="${tf_prefix}link_4"/>
        <axis xyz="0.0 0.0 1.0"/>
        <limit lower="-3.491" upper="3.491" velocity="6.11" effort="1000"/> 
    </joint>

    <!-- Link4 -->
    <link name="${tf_prefix}link_4">
      <visual>
        <origin xyz="0 0 0" rpy="0 0 0"/>
        <geometry>
          <mesh filename="package://fanuc_m16ib_description/meshes/visual/link4.stl" scale="0.001 0.001 0.001"/>
        </geometry>
        <material name="${tf_prefix}yellow"/>
      </visual>
      <collision>
        <origin xyz="0 0 0" rpy = "0 0 0"/>
        <geometry>
          <mesh filename="package://fanuc_m16ib_description/meshes/collision/link4.stl" scale="0.001 0.001 0.001"/>
        </geometry>
        <material name="${tf_prefix}red"/>
      </collision>
    </link>

    <!-- Joint 5 <limit lower="-2.443" upper="2.443" velocity="5.93" effort="1000"/>-->
    <joint name="${tf_prefix}joint5" type="revolute">
        <origin xyz="-0.04679 0 -0.55593" rpy="0 1.5707 0"/> 
        <parent link="${tf_prefix}link_4"/>
        <child link="${tf_prefix}link_5"/>
        <axis xyz="0.0 0.0 1.0"/>
        <limit lower="-1.5707" upper="1.5707" velocity="5.93" effort="1000"/> 
    </joint>

    <!-- Link5 -->
    <link name="${tf_prefix}link_5">
      <visual>
        <origin xyz="0 0 0" rpy="0 0 0"/>
        <geometry>
          <mesh filename="package://fanuc_m16ib_description/meshes/visual/link5.stl" scale="0.001 0.001 0.001"/>
        </geometry>
        <material name="${tf_prefix}yellow"/>
      </visual>
      <collision>
        <origin xyz="0 0 0" rpy = "0 0 0"/>
        <geometry>
          <mesh filename="package://fanuc_m16ib_description/meshes/collision/link5.stl" scale="0.001 0.001 0.001"/>
        </geometry>
        <material name="${tf_prefix}red"/>
      </collision>
    </link>

    <!-- Joint 6 <limit lower="-7.854" upper="7.854" velocity="9.08" effort="1000"/> -->
    <joint name="${tf_prefix}joint6" type="revolute">
        <origin xyz="0.080645 0 0.044376" rpy="0 1.5707 0"/> 
        <parent link="${tf_prefix}link_5"/>
        <child link="${tf_prefix}link_6"/>
        <axis xyz="0.0 0.0 1.0"/>
        <limit lower="-3.1415" upper="3.1415" velocity="9.08" effort="1000"/> 
    </joint>

    <!-- Link6 = Flange -->
    <link name="${tf_prefix}link_6">
      <visual>
        <origin xyz="0 0 0" rpy="0 0 0"/>
        <geometry>
          <mesh filename="package://fanuc_m16ib_description/meshes/visual/link6.stl" scale="0.001 0.001 0.001"/>
        </geometry>
        <material name="${tf_prefix}grey"/>
      </visual>
      <collision>
        <origin xyz="0 0 0" rpy = "0 0 0"/>
        <geometry>
          <mesh filename="package://fanuc_m16ib_description/meshes/collision/link6.stl" scale="0.001 0.001 0.001"/>
        </geometry>
        <material name="${tf_prefix}red"/>
      </collision>
    </link>

        <!-- Joint to Tool0/ Flange -->
        <joint name="${tf_prefix}to_tool0" type="fixed">
          <origin xyz="0 0 0.0196" rpy="0 0 0"/> 
          <parent link="${tf_prefix}link_6"/>
          <child link="${tf_prefix}tool0"/>
      </joint>
  
      <!-- tool0 -->
      <link name="${tf_prefix}tool0"/>
 
  
  </xacro:macro>
</robot>